Workbook
Name PT_Heat: 'Pivot Report SHEET '!$A$11
Name PT_TIME: 'Pivot Report SHEET '!$A$21
Name PT_Trend: 'Pivot Report SHEET '!$H$3
Name Slicer_Month: #N/A
Name Slicer_Year: #N/A
Name Slicer_Year1: #N/A

Sheet Raw Data(Hospital Room)
A1: Patient Id | B1: Patient Admission Date | C1: Patient Gender | D1: Patient Age | E1: Patient Race | F1: Department Referral | G1: Patient Admission Flag | H1: Patient Satisfaction Score | I1: Patient Waittime | J1: Patient Admission Flag2 | K1: Year | L1: Month | M1: Weekday | N1: Time block | O1: Agegroup | P1: WaitBand | Q1: WithinTarget | R1: Admitted Flag | S1: Satiesfied Flag | T1: Gender Clean
A2: P0001 | B2: 45371.366 | C2: M | D2: 69 | E2: White | F2: None | G2: FALSE | H2: 10 | I2: 39 | J2: FALSE | K2: =YEAR(Table1[[#This Row],[Patient Admission Date]]) -> 2024 | L2: =TEXT(Table1[[#This Row],[Patient Admission Date]],"mmm") -> Mar | M2: =TEXT(Table1[[#This Row],[Patient Admission Date]],"ddd") -> Wed | N2: =TEXT(INT(HOUR(Table1[[#This Row],[Patient Admission Date]])/3)*3,"00")&"-"&TEXT(INT(HOUR(Table1[[#This Row],[Patient Admission Date]])/3)*3+3,"00") -> 06-09 | O2: {=_xlfn.IFS(Table1[[#This Row],[Patient Age]]<=14,"0-14",Table1[[#This Row],[Patient Age]]<=29,"15-29",Table1[[#This Row],[Patient Age]]<=44,"30-44",Table1[[#This Row],[Patient Age]]<=59,"45-59",Table1[[#This Row],[Patient Age]]<=74,"60-74",TRUE,"75+")} -> 60-74 | P2: {=_xlfn.IFS(Table1[[#This Row],[Patient Waittime]]<=15,"0-15",Table1[[#This Row],[Patient Waittime]]<=30,"16-30",Table1[[#This Row],[Patient Waittime]]<=45,"31-45",Table1[[#This Row],[Patient Waittime]]<=60,"46-60",TRUE,"60+")} -> 31-45 | Q2: =--(Table1[[#This Row],[Patient Waittime]]<=30) -> 0 | R2: =--Table1[[#This Row],[Patient Admission Flag]] -> 0 | S2: =--AND(Table1[[#This Row],[WithinTarget]]=1,Table1[[#This Row],[Patient Satisfaction Score]]>=7) -> 0 | T2: =IF(LEFT(Table1[[#This Row],[Patient Gender]],1)="F","Female","Male") -> Male
A3: P0002 | B3: 45458.478 | C3: M | D3: 4 | E3: Native American/Alaska Native | F3: None | G3: TRUE | I3: 27 | J3: TRUE | K3: =YEAR(Table1[[#This Row],[Patient Admission Date]]) -> 2024 | L3: =TEXT(Table1[[#This Row],[Patient Admission Date]],"mmm") -> Jun | M3: =TEXT(Table1[[#This Row],[Patient Admission Date]],"ddd") -> Sat | N3: =TEXT(INT(HOUR(Table1[[#This Row],[Patient Admission Date]])/3)*3,"00")&"-"&TEXT(INT(HOUR(Table1[[#This Row],[Patient Admission Date]])/3)*3+3,"00") -> 09-12 | O3: {=_xlfn.IFS(Table1[[#This Row],[Patient Age]]<=14,"0-14",Table1[[#This Row],[Patient Age]]<=29,"15-29",Table1[[#This Row],[Patient Age]]<=44,"30-44",Table1[[#This Row],[Patient Age]]<=59,"45-59",Table1[[#This Row],[Patient Age]]<=74,"60-74",TRUE,"75+")} -> 0-14 | P3: {=_xlfn.IFS(Table1[[#This Row],[Patient Waittime]]<=15,"0-15",Table1[[#This Row],[Patient Waittime]]<=30,"16-30",Table1[[#This Row],[Patient Waittime]]<=45,"31-45",Table1[[#This Row],[Patient Waittime]]<=60,"46-60",TRUE,"60+")} -> 16-30 | Q3: =--(Table1[[#This Row],[Patient Waittime]]<=30) -> 1 | R3: =--Table1[[#This Row],[Patient Admission Flag]] -> 1 | S3: =--AND(Table1[[#This Row],[WithinTarget]]=1,Table1[[#This Row],[Patient Satisfaction Score]]>=7) -> 0 | T3: =IF(LEFT(Table1[[#This Row],[Patient Gender]],1)="F","Female","Male") -> Male
A4: P0003 | B4: 45463.384 | C4: F | D4: 56 | E4: African American | F4: General Practice | G4: TRUE | H4: 9 | I4: 55 | J4: TRUE | K4: =YEAR(Table1[[#This Row],[Patient Admission Date]]) -> 2024 | L4: =TEXT(Table1[[#This Row],[Patient Admission Date]],"mmm") -> Jun | M4: =TEXT(Table1[[#This Row],[Patient Admission Date]],"ddd") -> Thu | N4: =TEXT(INT(HOUR(Table1[[#This Row],[Patient Admission Date]])/3)*3,"00")&"-"&TEXT(INT(HOUR(Table1[[#This Row],[Patient Admission Date]])/3)*3+3,"00") -> 09-12 | O4: {=_xlfn.IFS(Table1[[#This Row],[Patient Age]]<=14,"0-14",Table1[[#This Row],[Patient Age]]<=29,"15-29",Table1[[#This Row],[Patient Age]]<=44,"30-44",Table1[[#This Row],[Patient Age]]<=59,"45-59",Table1[[#This Row],[Patient Age]]<=74,"60-74",TRUE,"75+")} -> 45-59 | P4: {=_xlfn.IFS(Table1[[#This Row],[Patient Waittime]]<=15,"0-15",Table1[[#This Row],[Patient Waittime]]<=30,"16-30",Table1[[#This Row],[Patient Waittime]]<=45,"31-45",Table1[[#This Row],[Patient Waittime]]<=60,"46-60",TRUE,"60+")} -> 46-60 | Q4: =--(Table1[[#This Row],[Patient Waittime]]<=30) -> 0 | R4: =--Table1[[#This Row],[Patient Admission Flag]] -> 1 | S4: =--AND(Table1[[#This Row],[WithinTarget]]=1,Table1[[#This Row],[Patient Satisfaction Score]]>=7) -> 0 | T4: =IF(LEFT(Table1[[#This Row],[Patient Gender]],1)="F","Female","Male") -> Female
A5: P0004 | B5: 45326.94 | C5: F | D5: 24 | E5: Native American/Alaska Native | F5: General Practice | G5: TRUE | H5: 8 | I5: 31 | J5: TRUE | K5: =YEAR(Table1[[#This Row],[Patient Admission Date]]) -> 2024 | L5: =TEXT(Table1[[#This Row],[Patient Admission Date]],"mmm") -> Feb | M5: =TEXT(Table1[[#This Row],[Patient Admission Date]],"ddd") -> Sun | N5: =TEXT(INT(HOUR(Table1[[#This Row],[Patient Admission Date]])/3)*3,"00")&"-"&TEXT(INT(HOUR(Table1[[#This Row],[Patient Admission Date]])/3)*3+3,"00") -> 21-24 | O5: {=_xlfn.IFS(Table1[[#This Row],[Patient Age]]<=14,"0-14",Table1[[#This Row],[Patient Age]]<=29,"15-29",Table1[[#This Row],[Patient Age]]<=44,"30-44",Table1[[#This Row],[Patient Age]]<=59,"45-59",Table1[[#This Row],[Patient Age]]<=74,"60-74",TRUE,"75+")} -> 15-29 | P5: {=_xlfn.IFS(Table1[[#This Row],[Patient Waittime]]<=15,"0-15",Table1[[#This Row],[Patient Waittime]]<=30,"16-30",Table1[[#This Row],[Patient Waittime]]<=45,"31-45",Table1[[#This Row],[Patient Waittime]]<=60,"46-60",TRUE,"60+")} -> 31-45 | Q5: =--(Table1[[#This Row],[Patient Waittime]]<=30) -> 0 | R5: =--Table1[[#This Row],[Patient Admission Flag]] -> 1 | S5: =--AND(Table1[[#This Row],[WithinTarget]]=1,Table1[[#This Row],[Patient Satisfaction Score]]>=7) -> 0 | T5: =IF(LEFT(Table1[[#This Row],[Patient Gender]],1)="F","Female","Male") -> Female
A6: P0005 | B6: 45539.742 | C6: Male | D6: 5 | E6: African American | F6: Orthopedics | G6: FALSE | I6: 10 | J6: FALSE | K6: =YEAR(Table1[[#This Row],[Patient Admission Date]]) -> 2024 | L6: =TEXT(Table1[[#This Row],[Patient Admission Date]],"mmm") -> Sep | M6: =TEXT(Table1[[#This Row],[Patient Admission Date]],"ddd") -> Wed | N6: =TEXT(INT(HOUR(Table1[[#This Row],[Patient Admission Date]])/3)*3,"00")&"-"&TEXT(INT(HOUR(Table1[[#This Row],[Patient Admission Date]])/3)*3+3,"00") -> 15-18 | O6: {=_xlfn.IFS(Table1[[#This Row],[Patient Age]]<=14,"0-14",Table1[[#This Row],[Patient Age]]<=29,"15-29",Table1[[#This Row],[Patient Age]]<=44,"30-44",Table1[[#This Row],[Patient Age]]<=59,"45-59",Table1[[#This Row],[Patient Age]]<=74,"60-74",TRUE,"75+")} -> 0-14 | P6: {=_xlfn.IFS(Table1[[#This Row],[Patient Waittime]]<=15,"0-15",Table1[[#This Row],[Patient Waittime]]<=30,"16-30",Table1[[#This Row],[Patient Waittime]]<=45,"31-45",Table1[[#This Row],[Patient Waittime]]<=60,"46-60",TRUE,"60+")} -> 0-15 | Q6: =--(Table1[[#This Row],[Patient Waittime]]<=30) -> 1 | R6: =--Table1[[#This Row],[Patient Admission Flag]] -> 0 | S6: =--AND(Table1[[#This Row],[WithinTarget]]=1,Table1[[#This Row],[Patient Satisfaction Score]]>=7) -> 0 | T6: =IF(LEFT(Table1[[#This Row],[Patient Gender]],1)="F","Female","Male") -> Male
A7: P0006 | B7: 45036.009 | C7: M | D7: 58 | E7: Asian | F7: None | G7: FALSE | I7: 59 | J7: FALSE | K7: =YEAR(Table1[[#This Row],[Patient Admission Date]]) -> 2023 | L7: =TEXT(Table1[[#This Row],[Patient Admission Date]],"mmm") -> Apr | M7: =TEXT(Table1[[#This Row],[Patient Admission Date]],"ddd") -> Thu | N7: =TEXT(INT(HOUR(Table1[[#This Row],[Patient Admission Date]])/3)*3,"00")&"-"&TEXT(INT(HOUR(Table1[[#This Row],[Patient Admission Date]])/3)*3+3,"00") -> 00-03 | O7: {=_xlfn.IFS(Table1[[#This Row],[Patient Age]]<=14,"0-14",Table1[[#This Row],[Patient Age]]<=29,"15-29",Table1[[#This Row],[Patient Age]]<=44,"30-44",Table1[[#This Row],[Patient Age]]<=59,"45-59",Table1[[#This Row],[Patient Age]]<=74,"60-74",TRUE,"75+")} -> 45-59 | P7: {=_xlfn.IFS(Table1[[#This Row],[Patient Waittime]]<=15,"0-15",Table1[[#This Row],[Patient Waittime]]<=30,"16-30",Table1[[#This Row],[Patient Waittime]]<=45,"31-45",Table1[[#This Row],[Patient Waittime]]<=60,"46-60",TRUE,"60+")} -> 46-60 | Q7: =--(Table1[[#This Row],[Patient Waittime]]<=30) -> 0 | R7: =--Table1[[#This Row],[Patient Admission Flag]] -> 0 | S7: =--AND(Table1[[#This Row],[WithinTarget]]=1,Table1[[#This Row],[Patient Satisfaction Score]]>=7) -> 0 | T7: =IF(LEFT(Table1[[#This Row],[Patient Gender]],1)="F","Female","Male") -> Male
A8: P0007 | B8: 45161.351 | C8: F | D8: 68 | E8: White | F8: None | G8: TRUE | I8: 43 | J8: TRUE | K8: =YEAR(Table1[[#This Row],[Patient Admission Date]]) -> 2023 | L8: =TEXT(Table1[[#This Row],[Patient Admission Date]],"mmm") -> Aug | M8: =TEXT(Table1[[#This Row],[Patient Admission Date]],"ddd") -> Wed | N8: =TEXT(INT(HOUR(Table1[[#This Row],[Patient Admission Date]])/3)*3,"00")&"-"&TEXT(INT(HOUR(Table1[[#This Row],[Patient Admission Date]])/3)*3+3,"00") -> 06-09 | O8: {=_xlfn.IFS(Table1[[#This Row],[Patient Age]]<=14,"0-14",Table1[[#This Row],[Patient Age]]<=29,"15-29",Table1[[#This Row],[Patient Age]]<=44,"30-44",Table1[[#This Row],[Patient Age]]<=59,"45-59",Table1[[#This Row],[Patient Age]]<=74,"60-74",TRUE,"75+")} -> 60-74 | P8: {=_xlfn.IFS(Table1[[#This Row],[Patient Waittime]]<=15,"0-15",Table1[[#This Row],[Patient Waittime]]<=30,"16-30",Table1[[#This Row],[Patient Waittime]]<=45,"31-45",Table1[[#This Row],[Patient Waittime]]<=60,"46-60",TRUE,"60+")} -> 31-45 | Q8: =--(Table1[[#This Row],[Patient Waittime]]<=30) -> 0 | R8: =--Table1[[#This Row],[Patient Admission Flag]] -> 1 | S8: =--AND(Table1[[#This Row],[WithinTarget]]=1,Table1[[#This Row],[Patient Satisfaction Score]]>=7) -> 0 | T8: =IF(LEFT(Table1[[#This Row],[Patient Gender]],1)="F","Female","Male") -> Female
A9: P0008 | B9: 45136.706 | C9: F | D9: 47 | E9: Two or More Races | F9: None | G9: TRUE | I9: 23 | J9: TRUE | K9: =YEAR(Table1[[#This Row],[Patient Admission Date]]) -> 2023 | L9: =TEXT(Table1[[#This Row],[Patient Admission Date]],"mmm") -> Jul | M9: =TEXT(Table1[[#This Row],[Patient Admission Date]],"ddd") -> Sat | N9: =TEXT(INT(HOUR(Table1[[#This Row],[Patient Admission Date]])/3)*3,"00")&"-"&TEXT(INT(HOUR(Table1[[#This Row],[Patient Admission Date]])/3)*3+3,"00") -> 15-18 | O9: {=_xlfn.IFS(Table1[[#This Row],[Patient Age]]<=14,"0-14",Table1[[#This Row],[Patient Age]]<=29,"15-29",Table1[[#This Row],[Patient Age]]<=44,"30-44",Table1[[#This Row],[Patient Age]]<=59,"45-59",Table1[[#This Row],[Patient Age]]<=74,"60-74",TRUE,"75+")} -> 45-59 | P9: {=_xlfn.IFS(Table1[[#This Row],[Patient Waittime]]<=15,"0-15",Table1[[#This Row],[Patient Waittime]]<=30,"16-30",Table1[[#This Row],[Patient Waittime]]<=45,"31-45",Table1[[#This Row],[Patient Waittime]]<=60,"46-60",TRUE,"60+")} -> 16-30 | Q9: =--(Table1[[#This Row],[Patient Waittime]]<=30) -> 1 | R9: =--Table1[[#This Row],[Patient Admission Flag]] -> 1 | S9: =--AND(Table1[[#This Row],[WithinTarget]]=1,Table1[[#This Row],[Patient Satisfaction Score]]>=7) -> 0 | T9: =IF(LEFT(Table1[[#This Row],[Patient Gender]],1)="F","Female","Male") -> Female
A10: P0009 | B10: 45341.287 | C10: F | D10: 79 | E10: White | F10: None | G10: FALSE | H10: 1 | I10: 42 | J10: FALSE | K10: =YEAR(Table1[[#This Row],[Patient Admission Date]]) -> 2024 | L10: =TEXT(Table1[[#This Row],[Patient Admission Date]],"mmm") -> Feb | M10: =TEXT(Table1[[#This Row],[Patient Admission Date]],"ddd") -> Mon | N10: =TEXT(INT(HOUR(Table1[[#This Row],[Patient Admission Date]])/3)*3,"00")&"-"&TEXT(INT(HOUR(Table1[[#This Row],[Patient Admission Date]])/3)*3+3,"00") -> 06-09 | O10: {=_xlfn.IFS(Table1[[#This Row],[Patient Age]]<=14,"0-14",Table1[[#This Row],[Patient Age]]<=29,"15-29",Table1[[#This Row],[Patient Age]]<=44,"30-44",Table1[[#This Row],[Patient Age]]<=59,"45-59",Table1[[#This Row],[Patient Age]]<=74,"60-74",TRUE,"75+")} -> 75+ | P10: {=_xlfn.IFS(Table1[[#This Row],[Patient Waittime]]<=15,"0-15",Table1[[#This Row],[Patient Waittime]]<=30,"16-30",Table1[[#This Row],[Patient Waittime]]<=45,"31-45",Table1[[#This Row],[Patient Waittime]]<=60,"46-60",TRUE,"60+")} -> 31-45 | Q10: =--(Table1[[#This Row],[Patient Waittime]]<=30) -> 0 | R10: =--Table1[[#This Row],[Patient Admission Flag]] -> 0 | S10: =--AND(Table1[[#This Row],[WithinTarget]]=1,Table1[[#This Row],[Patient Satisfaction Score]]>=7) -> 0 | T10: =IF(LEFT(Table1[[#This Row],[Patient Gender]],1)="F","Female","Male") -> Female
A11: P0010 | B11: 45576.226 | C11: Male | D11: 62 | E11: African American | F11: None | G11: FALSE | I11: 51 | J11: FALSE | K11: =YEAR(Table1[[#This Row],[Patient Admission Date]]) -> 2024 | L11: =TEXT(Table1[[#This Row],[Patient Admission Date]],"mmm") -> Oct | M11: =TEXT(Table1[[#This Row],[Patient Admission Date]],"ddd") -> Fri | N11: =TEXT(INT(HOUR(Table1[[#This Row],[Patient Admission Date]])/3)*3,"00")&"-"&TEXT(INT(HOUR(Table1[[#This Row],[Patient Admission Date]])/3)*3+3,"00") -> 03-06 | O11: {=_xlfn.IFS(Table1[[#This Row],[Patient Age]]<=14,"0-14",Table1[[#This Row],[Patient Age]]<=29,"15-29",Table1[[#This Row],[Patient Age]]<=44,"30-44",Table1[[#This Row],[Patient Age]]<=59,"45-59",Table1[[#This Row],[Patient Age]]<=74,"60-74",TRUE,"75+")} -> 60-74 | P11: {=_xlfn.IFS(Table1[[#This Row],[Patient Waittime]]<=15,"0-15",Table1[[#This Row],[Patient Waittime]]<=30,"16-30",Table1[[#This Row],[Patient Waittime]]<=45,"31-45",Table1[[#This Row],[Patient Waittime]]<=60,"46-60",TRUE,"60+")} -> 46-60 | Q11: =--(Table1[[#This Row],[Patient Waittime]]<=30) -> 0 | R11: =--Table1[[#This Row],[Patient Admission Flag]] -> 0 | S11: =--AND(Table1[[#This Row],[WithinTarget]]=1,Table1[[#This Row],[Patient Satisfaction Score]]>=7) -> 0 | T11: =IF(LEFT(Table1[[#This Row],[Patient Gender]],1)="F","Female","Male") -> Male
A12: P0011 | B12: 45499.073 | C12: F | D12: 73 | E12: White | F12: Gastroenterology | G12: TRUE | I12: 34 | J12: TRUE | K12: =YEAR(Table1[[#This Row],[Patient Admission Date]]) -> 2024 | L12: =TEXT(Table1[[#This Row],[Patient Admission Date]],"mmm") -> Jul | M12: =TEXT(Table1[[#This Row],[Patient Admission Date]],"ddd") -> Fri | N12: =TEXT(INT(HOUR(Table1[[#This Row],[Patient Admission Date]])/3)*3,"00")&"-"&TEXT(INT(HOUR(Table1[[#This Row],[Patient Admission Date]])/3)*3+3,"00") -> 00-03 | O12: {=_xlfn.IFS(Table1[[#This Row],[Patient Age]]<=14,"0-14",Table1[[#This Row],[Patient Age]]<=29,"15-29",Table1[[#This Row],[Patient Age]]<=44,"30-44",Table1[[#This Row],[Patient Age]]<=59,"45-59",Table1[[#This Row],[Patient Age]]<=74,"60-74",TRUE,"75+")} -> 60-74 | P12: {=_xlfn.IFS(Table1[[#This Row],[Patient Waittime]]<=15,"0-15",Table1[[#This Row],[Patient Waittime]]<=30,"16-30",Table1[[#This Row],[Patient Waittime]]<=45,"31-45",Table1[[#This Row],[Patient Waittime]]<=60,"46-60",TRUE,"60+")} -> 31-45 | Q12: =--(Table1[[#This Row],[Patient Waittime]]<=30) -> 0 | R12: =--Table1[[#This Row],[Patient Admission Flag]] -> 1 | S12: =--AND(Table1[[#This Row],[WithinTarget]]=1,Table1[[#This Row],[Patient Satisfaction Score]]>=7) -> 0 | T12: =IF(LEFT(Table1[[#This Row],[Patient Gender]],1)="F","Female","Male") -> Female
A13: P0012 | B13: 45361.918 | C13: F | D13: 16 | E13: White | F13: Orthopedics | G13: FALSE | I13: 39 | J13: FALSE | K13: =YEAR(Table1[[#This Row],[Patient Admission Date]]) -> 2024 | L13: =TEXT(Table1[[#This Row],[Patient Admission Date]],"mmm") -> Mar | M13: =TEXT(Table1[[#This Row],[Patient Admission Date]],"ddd") -> Sun | N13: =TEXT(INT(HOUR(Table1[[#This Row],[Patient Admission Date]])/3)*3,"00")&"-"&TEXT(INT(HOUR(Table1[[#This Row],[Patient Admission Date]])/3)*3+3,"00") -> 21-24 | O13: {=_xlfn.IFS(Table1[[#This Row],[Patient Age]]<=14,"0-14",Table1[[#This Row],[Patient Age]]<=29,"15-29",Table1[[#This Row],[Patient Age]]<=44,"30-44",Table1[[#This Row],[Patient Age]]<=59,"45-59",Table1[[#This Row],[Patient Age]]<=74,"60-74",TRUE,"75+")} -> 15-29 | P13: {=_xlfn.IFS(Table1[[#This Row],[Patient Waittime]]<=15,"0-15",Table1[[#This Row],[Patient Waittime]]<=30,"16-30",Table1[[#This Row],[Patient Waittime]]<=45,"31-45",Table1[[#This Row],[Patient Waittime]]<=60,"46-60",TRUE,"60+")} -> 31-45 | Q13: =--(Table1[[#This Row],[Patient Waittime]]<=30) -> 0 | R13: =--Table1[[#This Row],[Patient Admission Flag]] -> 0 | S13: =--AND(Table1[[#This Row],[WithinTarget]]=1,Table1[[#This Row],[Patient Satisfaction Score]]>=7) -> 0 | T13: =IF(LEFT(Table1[[#This Row],[Patient Gender]],1)="F","Female","Male") -> Female
A14: P0013 | B14: 45242.667 | C14: F | D14: 16 | E14: Native American/Alaska Native | F14: General Practice | G14: TRUE | I14: 53 | J14: TRUE | K14: =YEAR(Table1[[#This Row],[Patient Admission Date]]) -> 2023 | L14: =TEXT(Table1[[#This Row],[Patient Admission Date]],"mmm") -> Nov | M14: =TEXT(Table1[[#This Row],[Patient Admission Date]],"ddd") -> Sun | N14: =TEXT(INT(HOUR(Table1[[#This Row],[Patient Admission Date]])/3)*3,"00")&"-"&TEXT(INT(HOUR(Table1[[#This Row],[Patient Admission Date]])/3)*3+3,"00") -> 15-18 | O14: {=_xlfn.IFS(Table1[[#This Row],[Patient Age]]<=14,"0-14",Table1[[#This Row],[Patient Age]]<=29,"15-29",Table1[[#This Row],[Patient Age]]<=44,"30-44",Table1[[#This Row],[Patient Age]]<=59,"45-59",Table1[[#This Row],[Patient Age]]<=74,"60-74",TRUE,"75+")} -> 15-29 | P14: {=_xlfn.IFS(Table1[[#This Row],[Patient Waittime]]<=15,"0-15",Table1[[#This Row],[Patient Waittime]]<=30,"16-30",Table1[[#This Row],[Patient Waittime]]<=45,"31-45",Table1[[#This Row],[Patient Waittime]]<=60,"46-60",TRUE,"60+")} -> 46-60 | Q14: =--(Table1[[#This Row],[Patient Waittime]]<=30) -> 0 | R14: =--Table1[[#This Row],[Patient Admission Flag]] -> 1 | S14: =--AND(Table1[[#This Row],[WithinTarget]]=1,Table1[[#This Row],[Patient Satisfaction Score]]>=7) -> 0 | T14: =IF(LEFT(Table1[[#This Row],[Patient Gender]],1)="F","Female","Male") -> Female
A15: P0014 | B15: 45102.403 | C15: M | D15: 46 | E15: Pacific Islander | F15: None | G15: FALSE | I15: 45 | J15: FALSE | K15: =YEAR(Table1[[#This Row],[Patient Admission Date]]) -> 2023 | L15: =TEXT(Table1[[#This Row],[Patient Admission Date]],"mmm") -> Jun | M15: =TEXT(Table1[[#This Row],[Patient Admission Date]],"ddd") -> Sun | N15: =TEXT(INT(HOUR(Table1[[#This Row],[Patient Admission Date]])/3)*3,"00")&"-"&TEXT(INT(HOUR(Table1[[#This Row],[Patient Admission Date]])/3)*3+3,"00") -> 09-12 | O15: {=_xlfn.IFS(Table1[[#This Row],[Patient Age]]<=14,"0-14",Table1[[#This Row],[Patient Age]]<=29,"15-29",Table1[[#This Row],[Patient Age]]<=44,"30-44",Table1[[#This Row],[Patient Age]]<=59,"45-59",Table1[[#This Row],[Patient Age]]<=74,"60-74",TRUE,"75+")} -> 45-59 | P15: {=_xlfn.IFS(Table1[[#This Row],[Patient Waittime]]<=15,"0-15",Table1[[#This Row],[Patient Waittime]]<=30,"16-30",Table1[[#This Row],[Patient Waittime]]<=45,"31-45",Table1[[#This Row],[Patient Waittime]]<=60,"46-60",TRUE,"60+")} -> 31-45 | Q15: =--(Table1[[#This Row],[Patient Waittime]]<=30) -> 0 | R15: =--Table1[[#This Row],[Patient Admission Flag]] -> 0 | S15: =--AND(Table1[[#This Row],[WithinTarget]]=1,Table1[[#This Row],[Patient Satisfaction Score]]>=7) -> 0 | T15: =IF(LEFT(Table1[[#This Row],[Patient Gender]],1)="F","Female","Male") -> Male
A16: P0015 | B16: 45050.553 | C16: Male | D16: 69 | E16: White | F16: None | G16: TRUE | I16: 49 | J16: TRUE | K16: =YEAR(Table1[[#This Row],[Patient Admission Date]]) -> 2023 | L16: =TEXT(Table1[[#This Row],[Patient Admission Date]],"mmm") -> May | M16: =TEXT(Table1[[#This Row],[Patient Admission Date]],"ddd") -> Thu | N16: =TEXT(INT(HOUR(Table1[[#This Row],[Patient Admission Date]])/3)*3,"00")&"-"&TEXT(INT(HOUR(Table1[[#This Row],[Patient Admission Date]])/3)*3+3,"00") -> 12-15 | O16: {=_xlfn.IFS(Table1[[#This Row],[Patient Age]]<=14,"0-14",Table1[[#This Row],[Patient Age]]<=29,"15-29",Table1[[#This Row],[Patient Age]]<=44,"30-44",Table1[[#This Row],[Patient Age]]<=59,"45-59",Table1[[#This Row],[Patient Age]]<=74,"60-74",TRUE,"75+")} -> 60-74 | P16: {=_xlfn.IFS(Table1[[#This Row],[Patient Waittime]]<=15,"0-15",Table1[[#This Row],[Patient Waittime]]<=30,"16-30",Table1[[#This Row],[Patient Waittime]]<=45,"31-45",Table1[[#This Row],[Patient Waittime]]<=60,"46-60",TRUE,"60+")} -> 46-60 | Q16: =--(Table1[[#This Row],[Patient Waittime]]<=30) -> 0 | R16: =--Table1[[#This Row],[Patient Admission Flag]] -> 1 | S16: =--AND(Table1[[#This Row],[WithinTarget]]=1,Table1[[#This Row],[Patient Satisfaction Score]]>=7) -> 0 | T16: =IF(LEFT(Table1[[#This Row],[Patient Gender]],1)="F","Female","Male") -> Male
A17: P0016 | B17: 45188.078 | C17: M | D17: 37 | E17: Declined to Identify | F17: None | G17: TRUE | I17: 57 | J17: TRUE | K17: =YEAR(Table1[[#This Row],[Patient Admission Date]]) -> 2023 | L17: =TEXT(Table1[[#This Row],[Patient Admission Date]],"mmm") -> Sep | M17: =TEXT(Table1[[#This Row],[Patient Admission Date]],"ddd") -> Tue | N17: =TEXT(INT(HOUR(Table1[[#This Row],[Patient Admission Date]])/3)*3,"00")&"-"&TEXT(INT(HOUR(Table1[[#This Row],[Patient Admission Date]])/3)*3+3,"00") -> 00-03 | O17: {=_xlfn.IFS(Table1[[#This Row],[Patient Age]]<=14,"0-14",Table1[[#This Row],[Patient Age]]<=29,"15-29",Table1[[#This Row],[Patient Age]]<=44,"30-44",Table1[[#This Row],[Patient Age]]<=59,"45-59",Table1[[#This Row],[Patient Age]]<=74,"60-74",TRUE,"75+")} -> 30-44 | P17: {=_xlfn.IFS(Table1[[#This Row],[Patient Waittime]]<=15,"0-15",Table1[[#This Row],[Patient Waittime]]<=30,"16-30",Table1[[#This Row],[Patient Waittime]]<=45,"31-45",Table1[[#This Row],[Patient Waittime]]<=60,"46-60",TRUE,"60+")} -> 46-60 | Q17: =--(Table1[[#This Row],[Patient Waittime]]<=30) -> 0 | R17: =--Table1[[#This Row],[Patient Admission Flag]] -> 1 | S17: =--AND(Table1[[#This Row],[WithinTarget]]=1,Table1[[#This Row],[Patient Satisfaction Score]]>=7) -> 0 | T17: =IF(LEFT(Table1[[#This Row],[Patient Gender]],1)="F","Female","Male") -> Male
A18: P0017 | B18: 45437.924 | C18: F | D18: 50 | E18: Asian | F18: General Practice | G18: FALSE | I18: 35 | J18: FALSE | K18: =YEAR(Table1[[#This Row],[Patient Admission Date]]) -> 2024 | L18: =TEXT(Table1[[#This Row],[Patient Admission Date]],"mmm") -> May | M18: =TEXT(Table1[[#This Row],[Patient Admission Date]],"ddd") -> Sat | N18: =TEXT(INT(HOUR(Table1[[#This Row],[Patient Admission Date]])/3)*3,"00")&"-"&TEXT(INT(HOUR(Table1[[#This Row],[Patient Admission Date]])/3)*3+3,"00") -> 21-24 | O18: {=_xlfn.IFS(Table1[[#This Row],[Patient Age]]<=14,"0-14",Table1[[#This Row],[Patient Age]]<=29,"15-29",Table1[[#This Row],[Patient Age]]<=44,"30-44",Table1[[#This Row],[Patient Age]]<=59,"45-59",Table1[[#This Row],[Patient Age]]<=74,"60-74",TRUE,"75+")} -> 45-59 | P18: {=_xlfn.IFS(Table1[[#This Row],[Patient Waittime]]<=15,"0-15",Table1[[#This Row],[Patient Waittime]]<=30,"16-30",Table1[[#This Row],[Patient Waittime]]<=45,"31-45",Table1[[#This Row],[Patient Waittime]]<=60,"46-60",TRUE,"60+")} -> 31-45 | Q18: =--(Table1[[#This Row],[Patient Waittime]]<=30) -> 0 | R18: =--Table1[[#This Row],[Patient Admission Flag]] -> 0 | S18: =--AND(Table1[[#This Row],[WithinTarget]]=1,Table1[[#This Row],[Patient Satisfaction Score]]>=7) -> 0 | T18: =IF(LEFT(Table1[[#This Row],[Patient Gender]],1)="F","Female","Male") -> Female
A19: P0018 | B19: 45102.791 | C19: M | D19: 37 | E19: Declined to Identify | F19: None | G19: FALSE | I19: 55 | J19: FALSE | K19: =YEAR(Table1[[#This Row],[Patient Admission Date]]) -> 2023 | L19: =TEXT(Table1[[#This Row],[Patient Admission Date]],"mmm") -> Jun | M19: =TEXT(Table1[[#This Row],[Patient Admission Date]],"ddd") -> Sun | N19: =TEXT(INT(HOUR(Table1[[#This Row],[Patient Admission Date]])/3)*3,"00")&"-"&TEXT(INT(HOUR(Table1[[#This Row],[Patient Admission Date]])/3)*3+3,"00") -> 18-21 | O19: {=_xlfn.IFS(Table1[[#This Row],[Patient Age]]<=14,"0-14",Table1[[#This Row],[Patient Age]]<=29,"15-29",Table1[[#This Row],[Patient Age]]<=44,"30-44",Table1[[#This Row],[Patient Age]]<=59,"45-59",Table1[[#This Row],[Patient Age]]<=74,"60-74",TRUE,"75+")} -> 30-44 | P19: {=_xlfn.IFS(Table1[[#This Row],[Patient Waittime]]<=15,"0-15",Table1[[#This Row],[Patient Waittime]]<=30,"16-30",Table1[[#This Row],[Patient Waittime]]<=45,"31-45",Table1[[#This Row],[Patient Waittime]]<=60,"46-60",TRUE,"60+")} -> 46-60 | Q19: =--(Table1[[#This Row],[Patient Waittime]]<=30) -> 0 | R19: =--Table1[[#This Row],[Patient Admission Flag]] -> 0 | S19: =--AND(Table1[[#This Row],[WithinTarget]]=1,Table1[[#This Row],[Patient Satisfaction Score]]>=7) -> 0 | T19: =IF(LEFT(Table1[[#This Row],[Patient Gender]],1)="F","Female","Male") -> Male
A20: P0019 | B20: 45173.677 | C20: F | D20: 70 | E20: Asian | F20: Physiotherapy | G20: TRUE | I20: 50 | J20: TRUE | K20: =YEAR(Table1[[#This Row],[Patient Admission Date]]) -> 2023 | L20: =TEXT(Table1[[#This Row],[Patient Admission Date]],"mmm") -> Sep | M20: =TEXT(Table1[[#This Row],[Patient Admission Date]],"ddd") -> Mon | N20: =TEXT(INT(HOUR(Table1[[#This Row],[Patient Admission Date]])/3)*3,"00")&"-"&TEXT(INT(HOUR(Table1[[#This Row],[Patient Admission Date]])/3)*3+3,"00") -> 15-18 | O20: {=_xlfn.IFS(Table1[[#This Row],[Patient Age]]<=14,"0-14",Table1[[#This Row],[Patient Age]]<=29,"15-29",Table1[[#This Row],[Patient Age]]<=44,"30-44",Table1[[#This Row],[Patient Age]]<=59,"45-59",Table1[[#This Row],[Patient Age]]<=74,"60-74",TRUE,"75+")} -> 60-74 | P20: {=_xlfn.IFS(Table1[[#This Row],[Patient Waittime]]<=15,"0-15",Table1[[#This Row],[Patient Waittime]]<=30,"16-30",Table1[[#This Row],[Patient Waittime]]<=45,"31-45",Table1[[#This Row],[Patient Waittime]]<=60,"46-60",TRUE,"60+")} -> 46-60 | Q20: =--(Table1[[#This Row],[Patient Waittime]]<=30) -> 0 | R20: =--Table1[[#This Row],[Patient Admission Flag]] -> 1 | S20: =--AND(Table1[[#This Row],[WithinTarget]]=1,Table1[[#This Row],[Patient Satisfaction Score]]>=7) -> 0 | T20: =IF(LEFT(Table1[[#This Row],[Patient Gender]],1)="F","Female","Male") -> Female
A21: P0020 | B21: 45246.99 | C21: M | D21: 55 | E21: Asian | F21: None | G21: TRUE | H21: 2 | I21: 40 | J21: TRUE | K21: =YEAR(Table1[[#This Row],[Patient Admission Date]]) -> 2023 | L21: =TEXT(Table1[[#This Row],[Patient Admission Date]],"mmm") -> Nov | M21: =TEXT(Table1[[#This Row],[Patient Admission Date]],"ddd") -> Thu | N21: =TEXT(INT(HOUR(Table1[[#This Row],[Patient Admission Date]])/3)*3,"00")&"-"&TEXT(INT(HOUR(Table1[[#This Row],[Patient Admission Date]])/3)*3+3,"00") -> 21-24 | O21: {=_xlfn.IFS(Table1[[#This Row],[Patient Age]]<=14,"0-14",Table1[[#This Row],[Patient Age]]<=29,"15-29",Table1[[#This Row],[Patient Age]]<=44,"30-44",Table1[[#This Row],[Patient Age]]<=59,"45-59",Table1[[#This Row],[Patient Age]]<=74,"60-74",TRUE,"75+")} -> 45-59 | P21: {=_xlfn.IFS(Table1[[#This Row],[Patient Waittime]]<=15,"0-15",Table1[[#This Row],[Patient Waittime]]<=30,"16-30",Table1[[#This Row],[Patient Waittime]]<=45,"31-45",Table1[[#This Row],[Patient Waittime]]<=60,"46-60",TRUE,"60+")} -> 31-45 | Q21: =--(Table1[[#This Row],[Patient Waittime]]<=30) -> 0 | R21: =--Table1[[#This Row],[Patient Admission Flag]] -> 1 | S21: =--AND(Table1[[#This Row],[WithinTarget]]=1,Table1[[#This Row],[Patient Satisfaction Score]]>=7) -> 0 | T21: =IF(LEFT(Table1[[#This Row],[Patient Gender]],1)="F","Female","Male") -> Male
A22: P0021 | B22: 45107.224 | C22: F | D22: 63 | E22: Native American/Alaska Native | F22: None | G22: TRUE | I22: 25 | J22: TRUE | K22: =YEAR(Table1[[#This Row],[Patient Admission Date]]) -> 2023 | L22: =TEXT(Table1[[#This Row],[Patient Admission Date]],"mmm") -> Jun | M22: =TEXT(Table1[[#This Row],[Patient Admission Date]],"ddd") -> Fri | N22: =TEXT(INT(HOUR(Table1[[#This Row],[Patient Admission Date]])/3)*3,"00")&"-"&TEXT(INT(HOUR(Table1[[#This Row],[Patient Admission Date]])/3)*3+3,"00") -> 03-06 | O22: {=_xlfn.IFS(Table1[[#This Row],[Patient Age]]<=14,"0-14",Table1[[#This Row],[Patient Age]]<=29,"15-29",Table1[[#This Row],[Patient Age]]<=44,"30-44",Table1[[#This Row],[Patient Age]]<=59,"45-59",Table1[[#This Row],[Patient Age]]<=74,"60-74",TRUE,"75+")} -> 60-74 | P22: {=_xlfn.IFS(Table1[[#This Row],[Patient Waittime]]<=15,"0-15",Table1[[#This Row],[Patient Waittime]]<=30,"16-30",Table1[[#This Row],[Patient Waittime]]<=45,"31-45",Table1[[#This Row],[Patient Waittime]]<=60,"46-60",TRUE,"60+")} -> 16-30 | Q22: =--(Table1[[#This Row],[Patient Waittime]]<=30) -> 1 | R22: =--Table1[[#This Row],[Patient Admission Flag]] -> 1 | S22: =--AND(Table1[[#This Row],[WithinTarget]]=1,Table1[[#This Row],[Patient Satisfaction Score]]>=7) -> 0 | T22: =IF(LEFT(Table1[[#This Row],[Patient Gender]],1)="F","Female","Male") -> Female
A23: P0022 | B23: 45068.7 | C23: F | D23: 44 | E23: Asian | F23: None | G23: FALSE | H23: 2 | I23: 51 | J23: FALSE | K23: =YEAR(Table1[[#This Row],[Patient Admission Date]]) -> 2023 | L23: =TEXT(Table1[[#This Row],[Patient Admission Date]],"mmm") -> May | M23: =TEXT(Table1[[#This Row],[Patient Admission Date]],"ddd") -> Mon | N23: =TEXT(INT(HOUR(Table1[[#This Row],[Patient Admission Date]])/3)*3,"00")&"-"&TEXT(INT(HOUR(Table1[[#This Row],[Patient Admission Date]])/3)*3+3,"00") -> 15-18 | O23: {=_xlfn.IFS(Table1[[#This Row],[Patient Age]]<=14,"0-14",Table1[[#This Row],[Patient Age]]<=29,"15-29",Table1[[#This Row],[Patient Age]]<=44,"30-44",Table1[[#This Row],[Patient Age]]<=59,"45-59",Table1[[#This Row],[Patient Age]]<=74,"60-74",TRUE,"75+")} -> 30-44 | P23: {=_xlfn.IFS(Table1[[#This Row],[Patient Waittime]]<=15,"0-15",Table1[[#This Row],[Patient Waittime]]<=30,"16-30",Table1[[#This Row],[Patient Waittime]]<=45,"31-45",Table1[[#This Row],[Patient Waittime]]<=60,"46-60",TRUE,"60+")} -> 46-60 | Q23: =--(Table1[[#This Row],[Patient Waittime]]<=30) -> 0 | R23: =--Table1[[#This Row],[Patient Admission Flag]] -> 0 | S23: =--AND(Table1[[#This Row],[WithinTarget]]=1,Table1[[#This Row],[Patient Satisfaction Score]]>=7) -> 0 | T23: =IF(LEFT(Table1[[#This Row],[Patient Gender]],1)="F","Female","Male") -> Female
A24: P0023 | B24: 45247.308 | C24: Female | D24: 11 | E24: Declined to Identify | F24: None | G24: FALSE | H24: 4 | I24: 30 | J24: FALSE | K24: =YEAR(Table1[[#This Row],[Patient Admission Date]]) -> 2023 | L24: =TEXT(Table1[[#This Row],[Patient Admission Date]],"mmm") -> Nov | M24: =TEXT(Table1[[#This Row],[Patient Admission Date]],"ddd") -> Fri | N24: =TEXT(INT(HOUR(Table1[[#This Row],[Patient Admission Date]])/3)*3,"00")&"-"&TEXT(INT(HOUR(Table1[[#This Row],[Patient Admission Date]])/3)*3+3,"00") -> 06-09 | O24: {=_xlfn.IFS(Table1[[#This Row],[Patient Age]]<=14,"0-14",Table1[[#This Row],[Patient Age]]<=29,"15-29",Table1[[#This Row],[Patient Age]]<=44,"30-44",Table1[[#This Row],[Patient Age]]<=59,"45-59",Table1[[#This Row],[Patient Age]]<=74,"60-74",TRUE,"75+")} -> 0-14 | P24: {=_xlfn.IFS(Table1[[#This Row],[Patient Waittime]]<=15,"0-15",Table1[[#This Row],[Patient Waittime]]<=30,"16-30",Table1[[#This Row],[Patient Waittime]]<=45,"31-45",Table1[[#This Row],[Patient Waittime]]<=60,"46-60",TRUE,"60+")} -> 16-30 | Q24: =--(Table1[[#This Row],[Patient Waittime]]<=30) -> 1 | R24: =--Table1[[#This Row],[Patient Admission Flag]] -> 0 | S24: =--AND(Table1[[#This Row],[WithinTarget]]=1,Table1[[#This Row],[Patient Satisfaction Score]]>=7) -> 0 | T24: =IF(LEFT(Table1[[#This Row],[Patient Gender]],1)="F","Female","Male") -> Female
A25: P0024 | B25: 45317.249 | C25: M | D25: 8 | E25: Asian | F25: General Practice | G25: FALSE | I25: 16 | J25: FALSE | K25: =YEAR(Table1[[#This Row],[Patient Admission Date]]) -> 2024 | L25: =TEXT(Table1[[#This Row],[Patient Admission Date]],"mmm") -> Jan | M25: =TEXT(Table1[[#This Row],[Patient Admission Date]],"ddd") -> Fri | N25: =TEXT(INT(HOUR(Table1[[#This Row],[Patient Admission Date]])/3)*3,"00")&"-"&TEXT(INT(HOUR(Table1[[#This Row],[Patient Admission Date]])/3)*3+3,"00") -> 03-06 | O25: {=_xlfn.IFS(Table1[[#This Row],[Patient Age]]<=14,"0-14",Table1[[#This Row],[Patient Age]]<=29,"15-29",Table1[[#This Row],[Patient Age]]<=44,"30-44",Table1[[#This Row],[Patient Age]]<=59,"45-59",Table1[[#This Row],[Patient Age]]<=74,"60-74",TRUE,"75+")} -> 0-14 | P25: {=_xlfn.IFS(Table1[[#This Row],[Patient Waittime]]<=15,"0-15",Table1[[#This Row],[Patient Waittime]]<=30,"16-30",Table1[[#This Row],[Patient Waittime]]<=45,"31-45",Table1[[#This Row],[Patient Waittime]]<=60,"46-60",TRUE,"60+")} -> 16-30 | Q25: =--(Table1[[#This Row],[Patient Waittime]]<=30) -> 1 | R25: =--Table1[[#This Row],[Patient Admission Flag]] -> 0 | S25: =--AND(Table1[[#This Row],[WithinTarget]]=1,Table1[[#This Row],[Patient Satisfaction Score]]>=7) -> 0 | T25: =IF(LEFT(Table1[[#This Row],[Patient Gender]],1)="F","Female","Male") -> Male
A26: P0025 | B26: 45070.613 | C26: F | D26: 4 | E26: Native American/Alaska Native | F26: None | G26: TRUE | I26: 23 | J26: TRUE | K26: =YEAR(Table1[[#This Row],[Patient Admission Date]]) -> 2023 | L26: =TEXT(Table1[[#This Row],[Patient Admission Date]],"mmm") -> May | M26: =TEXT(Table1[[#This Row],[Patient Admission Date]],"ddd") -> Wed | N26: =TEXT(INT(HOUR(Table1[[#This Row],[Patient Admission Date]])/3)*3,"00")&"-"&TEXT(INT(HOUR(Table1[[#This Row],[Patient Admission Date]])/3)*3+3,"00") -> 12-15 | O26: {=_xlfn.IFS(Table1[[#This Row],[Patient Age]]<=14,"0-14",Table1[[#This Row],[Patient Age]]<=29,"15-29",Table1[[#This Row],[Patient Age]]<=44,"30-44",Table1[[#This Row],[Patient Age]]<=59,"45-59",Table1[[#This Row],[Patient Age]]<=74,"60-74",TRUE,"75+")} -> 0-14 | P26: {=_xlfn.IFS(Table1[[#This Row],[Patient Waittime]]<=15,"0-15",Table1[[#This Row],[Patient Waittime]]<=30,"16-30",Table1[[#This Row],[Patient Waittime]]<=45,"31-45",Table1[[#This Row],[Patient Waittime]]<=60,"46-60",TRUE,"60+")} -> 16-30 | Q26: =--(Table1[[#This Row],[Patient Waittime]]<=30) -> 1 | R26: =--Table1[[#This Row],[Patient Admission Flag]] -> 1 | S26: =--AND(Table1[[#This Row],[WithinTarget]]=1,Table1[[#This Row],[Patient Satisfaction Score]]>=7) -> 0 | T26: =IF(LEFT(Table1[[#This Row],[Patient Gender]],1)="F","Female","Male") -> Female
A27: P0026 | B27: 45028.876 | C27: M | D27: 42 | E27: African American | F27: None | G27: FALSE | H27: 0 | I27: 51 | J27: FALSE | K27: =YEAR(Table1[[#This Row],[Patient Admission Date]]) -> 2023 | L27: =TEXT(Table1[[#This Row],[Patient Admission Date]],"mmm") -> Apr | M27: =TEXT(Table1[[#This Row],[Patient Admission Date]],"ddd") -> Wed | N27: =TEXT(INT(HOUR(Table1[[#This Row],[Patient Admission Date]])/3)*3,"00")&"-"&TEXT(INT(HOUR(Table1[[#This Row],[Patient Admission Date]])/3)*3+3,"00") -> 21-24 | O27: {=_xlfn.IFS(Table1[[#This Row],[Patient Age]]<=14,"0-14",Table1[[#This Row],[Patient Age]]<=29,"15-29",Table1[[#This Row],[Patient Age]]<=44,"30-44",Table1[[#This Row],[Patient Age]]<=59,"45-59",Table1[[#This Row],[Patient Age]]<=74,"60-74",TRUE,"75+")} -> 30-44 | P27: {=_xlfn.IFS(Table1[[#This Row],[Patient Waittime]]<=15,"0-15",Table1[[#This Row],[Patient Waittime]]<=30,"16-30",Table1[[#This Row],[Patient Waittime]]<=45,"31-45",Table1[[#This Row],[Patient Waittime]]<=60,"46-60",TRUE,"60+")} -> 46-60 | Q27: =--(Table1[[#This Row],[Patient Waittime]]<=30) -> 0 | R27: =--Table1[[#This Row],[Patient Admission Flag]] -> 0 | S27: =--AND(Table1[[#This Row],[WithinTarget]]=1,Table1[[#This Row],[Patient Satisfaction Score]]>=7) -> 0 | T27: =IF(LEFT(Table1[[#This Row],[Patient Gender]],1)="F","Female","Male") -> Male
A28: P0027 | B28: 45539.104 | C28: F | D28: 68 | E28: African American | F28: None | G28: FALSE | I28: 58 | J28: FALSE | K28: =YEAR(Table1[[#This Row],[Patient Admission Date]]) -> 2024 | L28: =TEXT(Table1[[#This Row],[Patient Admission Date]],"mmm") -> Sep | M28: =TEXT(Table1[[#This Row],[Patient Admission Date]],"ddd") -> Wed | N28: =TEXT(INT(HOUR(Table1[[#This Row],[Patient Admission Date]])/3)*3,"00")&"-"&TEXT(INT(HOUR(Table1[[#This Row],[Patient Admission Date]])/3)*3+3,"00") -> 00-03 | O28: {=_xlfn.IFS(Table1[[#This Row],[Patient Age]]<=14,"0-14",Table1[[#This Row],[Patient Age]]<=29,"15-29",Table1[[#This Row],[Patient Age]]<=44,"30-44",Table1[[#This Row],[Patient Age]]<=59,"45-59",Table1[[#This Row],[Patient Age]]<=74,"60-74",TRUE,"75+")} -> 60-74 | P28: {=_xlfn.IFS(Table1[[#This Row],[Patient Waittime]]<=15,"0-15",Table1[[#This Row],[Patient Waittime]]<=30,"16-30",Table1[[#This Row],[Patient Waittime]]<=45,"31-45",Table1[[#This Row],[Patient Waittime]]<=60,"46-60",TRUE,"60+")} -> 46-60 | Q28: =--(Table1[[#This Row],[Patient Waittime]]<=30) -> 0 | R28: =--Table1[[#This Row],[Patient Admission Flag]] -> 0 | S28: =--AND(Table1[[#This Row],[WithinTarget]]=1,Table1[[#This Row],[Patient Satisfaction Score]]>=7) -> 0 | T28: =IF(LEFT(Table1[[#This Row],[Patient Gender]],1)="F","Female","Male") -> Female
A29: P0028 | B29: 45276.543 | C29: M | D29: 22 | E29: Pacific Islander | F29: General Practice | G29: FALSE | I29: 25 | J29: FALSE | K29: =YEAR(Table1[[#This Row],[Patient Admission Date]]) -> 2023 | L29: =TEXT(Table1[[#This Row],[Patient Admission Date]],"mmm") -> Dec | M29: =TEXT(Table1[[#This Row],[Patient Admission Date]],"ddd") -> Sat | N29: =TEXT(INT(HOUR(Table1[[#This Row],[Patient Admission Date]])/3)*3,"00")&"-"&TEXT(INT(HOUR(Table1[[#This Row],[Patient Admission Date]])/3)*3+3,"00") -> 12-15 | O29: {=_xlfn.IFS(Table1[[#This Row],[Patient Age]]<=14,"0-14",Table1[[#This Row],[Patient Age]]<=29,"15-29",Table1[[#This Row],[Patient Age]]<=44,"30-44",Table1[[#This Row],[Patient Age]]<=59,"45-59",Table1[[#This Row],[Patient Age]]<=74,"60-74",TRUE,"75+")} -> 15-29 | P29: {=_xlfn.IFS(Table1[[#This Row],[Patient Waittime]]<=15,"0-15",Table1[[#This Row],[Patient Waittime]]<=30,"16-30",Table1[[#This Row],[Patient Waittime]]<=45,"31-45",Table1[[#This Row],[Patient Waittime]]<=60,"46-60",TRUE,"60+")} -> 16-30 | Q29: =--(Table1[[#This Row],[Patient Waittime]]<=30) -> 1 | R29: =--Table1[[#This Row],[Patient Admission Flag]] -> 0 | S29: =--AND(Table1[[#This Row],[WithinTarget]]=1,Table1[[#This Row],[Patient Satisfaction Score]]>=7) -> 0 | T29: =IF(LEFT(Table1[[#This Row],[Patient Gender]],1)="F","Female","Male") -> Male
A30: P0029 | B30: 45362.713 | C30: F | D30: 58 | E30: Declined to Identify | F30: Orthopedics | G30: FALSE | I30: 55 | J30: FALSE | K30: =YEAR(Table1[[#This Row],[Patient Admission Date]]) -> 2024 | L30: =TEXT(Table1[[#This Row],[Patient Admission Date]],"mmm") -> Mar | M30: =TEXT(Table1[[#This Row],[Patient Admission Date]],"ddd") -> Mon | N30: =TEXT(INT(HOUR(Table1[[#This Row],[Patient Admission Date]])/3)*3,"00")&"-"&TEXT(INT(HOUR(Table1[[#This Row],[Patient Admission Date]])/3)*3+3,"00") -> 15-18 | O30: {=_xlfn.IFS(Table1[[#This Row],[Patient Age]]<=14,"0-14",Table1[[#This Row],[Patient Age]]<=29,"15-29",Table1[[#This Row],[Patient Age]]<=44,"30-44",Table1[[#This Row],[Patient Age]]<=59,"45-59",Table1[[#This Row],[Patient Age]]<=74,"60-74",TRUE,"75+")} -> 45-59 | P30: {=_xlfn.IFS(Table1[[#This Row],[Patient Waittime]]<=15,"0-15",Table1[[#This Row],[Patient Waittime]]<=30,"16-30",Table1[[#This Row],[Patient Waittime]]<=45,"31-45",Table1[[#This Row],[Patient Waittime]]<=60,"46-60",TRUE,"60+")} -> 46-60 | Q30: =--(Table1[[#This Row],[Patient Waittime]]<=30) -> 0 | R30: =--Table1[[#This Row],[Patient Admission Flag]] -> 0 | S30: =--AND(Table1[[#This Row],[WithinTarget]]=1,Table1[[#This Row],[Patient Satisfaction Score]]>=7) -> 0 | T30: =IF(LEFT(Table1[[#This Row],[Patient Gender]],1)="F","Female","Male") -> Female
A31: P0030 | B31: 45480.624 | C31: F | D31: 72 | E31: African American | F31: None | G31: TRUE | I31: 37 | J31: TRUE | K31: =YEAR(Table1[[#This Row],[Patient Admission Date]]) -> 2024 | L31: =TEXT(Table1[[#This Row],[Patient Admission Date]],"mmm") -> Jul | M31: =TEXT(Table1[[#This Row],[Patient Admission Date]],"ddd") -> Sun | N31: =TEXT(INT(HOUR(Table1[[#This Row],[Patient Admission Date]])/3)*3,"00")&"-"&TEXT(INT(HOUR(Table1[[#This Row],[Patient Admission Date]])/3)*3+3,"00") -> 12-15 | O31: {=_xlfn.IFS(Table1[[#This Row],[Patient Age]]<=14,"0-14",Table1[[#This Row],[Patient Age]]<=29,"15-29",Table1[[#This Row],[Patient Age]]<=44,"30-44",Table1[[#This Row],[Patient Age]]<=59,"45-59",Table1[[#This Row],[Patient Age]]<=74,"60-74",TRUE,"75+")} -> 60-74 | P31: {=_xlfn.IFS(Table1[[#This Row],[Patient Waittime]]<=15,"0-15",Table1[[#This Row],[Patient Waittime]]<=30,"16-30",Table1[[#This Row],[Patient Waittime]]<=45,"31-45",Table1[[#This Row],[Patient Waittime]]<=60,"46-60",TRUE,"60+")} -> 31-45 | Q31: =--(Table1[[#This Row],[Patient Waittime]]<=30) -> 0 | R31: =--Table1[[#This Row],[Patient Admission Flag]] -> 1 | S31: =--AND(Table1[[#This Row],[WithinTarget]]=1,Table1[[#This Row],[Patient Satisfaction Score]]>=7) -> 0 | T31: =IF(LEFT(Table1[[#This Row],[Patient Gender]],1)="F","Female","Male") -> Female
A32: P0031 | B32: 45384.555 | C32: F | D32: 73 | E32: Two or More Races | F32: Neurology | G32: FALSE | I32: 46 | J32: FALSE | K32: =YEAR(Table1[[#This Row],[Patient Admission Date]]) -> 2024 | L32: =TEXT(Table1[[#This Row],[Patient Admission Date]],"mmm") -> Apr | M32: =TEXT(Table1[[#This Row],[Patient Admission Date]],"ddd") -> Tue | N32: =TEXT(INT(HOUR(Table1[[#This Row],[Patient Admission Date]])/3)*3,"00")&"-"&TEXT(INT(HOUR(Table1[[#This Row],[Patient Admission Date]])/3)*3+3,"00") -> 12-15 | O32: {=_xlfn.IFS(Table1[[#This Row],[Patient Age]]<=14,"0-14",Table1[[#This Row],[Patient Age]]<=29,"15-29",Table1[[#This Row],[Patient Age]]<=44,"30-44",Table1[[#This Row],[Patient Age]]<=59,"45-59",Table1[[#This Row],[Patient Age]]<=74,"60-74",TRUE,"75+")} -> 60-74 | P32: {=_xlfn.IFS(Table1[[#This Row],[Patient Waittime]]<=15,"0-15",Table1[[#This Row],[Patient Waittime]]<=30,"16-30",Table1[[#This Row],[Patient Waittime]]<=45,"31-45",Table1[[#This Row],[Patient Waittime]]<=60,"46-60",TRUE,"60+")} -> 46-60 | Q32: =--(Table1[[#This Row],[Patient Waittime]]<=30) -> 0 | R32: =--Table1[[#This Row],[Patient Admission Flag]] -> 0 | S32: =--AND(Table1[[#This Row],[WithinTarget]]=1,Table1[[#This Row],[Patient Satisfaction Score]]>=7) -> 0 | T32: =IF(LEFT(Table1[[#This Row],[Patient Gender]],1)="F","Female","Male") -> Female
A33: P0032 | B33: 45107.943 | C33: M | D33: 35 | E33: White | F33: Orthopedics | G33: TRUE | I33: 40 | J33: TRUE | K33: =YEAR(Table1[[#This Row],[Patient Admission Date]]) -> 2023 | L33: =TEXT(Table1[[#This Row],[Patient Admission Date]],"mmm") -> Jun | M33: =TEXT(Table1[[#This Row],[Patient Admission Date]],"ddd") -> Fri | N33: =TEXT(INT(HOUR(Table1[[#This Row],[Patient Admission Date]])/3)*3,"00")&"-"&TEXT(INT(HOUR(Table1[[#This Row],[Patient Admission Date]])/3)*3+3,"00") -> 21-24 | O33: {=_xlfn.IFS(Table1[[#This Row],[Patient Age]]<=14,"0-14",Table1[[#This Row],[Patient Age]]<=29,"15-29",Table1[[#This Row],[Patient Age]]<=44,"30-44",Table1[[#This Row],[Patient Age]]<=59,"45-59",Table1[[#This Row],[Patient Age]]<=74,"60-74",TRUE,"75+")} -> 30-44 | P33: {=_xlfn.IFS(Table1[[#This Row],[Patient Waittime]]<=15,"0-15",Table1[[#This Row],[Patient Waittime]]<=30,"16-30",Table1[[#This Row],[Patient Waittime]]<=45,"31-45",Table1[[#This Row],[Patient Waittime]]<=60,"46-60",TRUE,"60+")} -> 31-45 | Q33: =--(Table1[[#This Row],[Patient Waittime]]<=30) -> 0 | R33: =--Table1[[#This Row],[Patient Admission Flag]] -> 1 | S33: =--AND(Table1[[#This Row],[WithinTarget]]=1,Table1[[#This Row],[Patient Satisfaction Score]]>=7) -> 0 | T33: =IF(LEFT(Table1[[#This Row],[Patient Gender]],1)="F","Female","Male") -> Male
A34: P0033 | B34: 45509.637 | C34: M | D34: 48 | E34: White | F34: None | G34: FALSE | I34: 53 | J34: FALSE | K34: =YEAR(Table1[[#This Row],[Patient Admission Date]]) -> 2024 | L34: =TEXT(Table1[[#This Row],[Patient Admission Date]],"mmm") -> Aug | M34: =TEXT(Table1[[#This Row],[Patient Admission Date]],"ddd") -> Mon | N34: =TEXT(INT(HOUR(Table1[[#This Row],[Patient Admission Date]])/3)*3,"00")&"-"&TEXT(INT(HOUR(Table1[[#This Row],[Patient Admission Date]])/3)*3+3,"00") -> 15-18 | O34: {=_xlfn.IFS(Table1[[#This Row],[Patient Age]]<=14,"0-14",Table1[[#This Row],[Patient Age]]<=29,"15-29",Table1[[#This Row],[Patient Age]]<=44,"30-44",Table1[[#This Row],[Patient Age]]<=59,"45-59",Table1[[#This Row],[Patient Age]]<=74,"60-74",TRUE,"75+")} -> 45-59 | P34: {=_xlfn.IFS(Table1[[#This Row],[Patient Waittime]]<=15,"0-15",Table1[[#This Row],[Patient Waittime]]<=30,"16-30",Table1[[#This Row],[Patient Waittime]]<=45,"31-45",Table1[[#This Row],[Patient Waittime]]<=60,"46-60",TRUE,"60+")} -> 46-60 | Q34: =--(Table1[[#This Row],[Patient Waittime]]<=30) -> 0 | R34: =--Table1[[#This Row],[Patient Admission Flag]] -> 0 | S34: =--AND(Table1[[#This Row],[WithinTarget]]=1,Table1[[#This Row],[Patient Satisfaction Score]]>=7) -> 0 | T34: =IF(LEFT(Table1[[#This Row],[Patient Gender]],1)="F","Female","Male") -> Male
A35: P0034 | B35: 45509.065 | C35: F | D35: 74 | E35: White | F35: Physiotherapy | G35: FALSE | H35: 0 | I35: 20 | J35: FALSE | K35: =YEAR(Table1[[#This Row],[Patient Admission Date]]) -> 2024 | L35: =TEXT(Table1[[#This Row],[Patient Admission Date]],"mmm") -> Aug | M35: =TEXT(Table1[[#This Row],[Patient Admission Date]],"ddd") -> Mon | N35: =TEXT(INT(HOUR(Table1[[#This Row],[Patient Admission Date]])/3)*3,"00")&"-"&TEXT(INT(HOUR(Table1[[#This Row],[Patient Admission Date]])/3)*3+3,"00") -> 00-03 | O35: {=_xlfn.IFS(Table1[[#This Row],[Patient Age]]<=14,"0-14",Table1[[#This Row],[Patient Age]]<=29,"15-29",Table1[[#This Row],[Patient Age]]<=44,"30-44",Table1[[#This Row],[Patient Age]]<=59,"45-59",Table1[[#This Row],[Patient Age]]<=74,"60-74",TRUE,"75+")} -> 60-74 | P35: {=_xlfn.IFS(Table1[[#This Row],[Patient Waittime]]<=15,"0-15",Table1[[#This Row],[Patient Waittime]]<=30,"16-30",Table1[[#This Row],[Patient Waittime]]<=45,"31-45",Table1[[#This Row],[Patient Waittime]]<=60,"46-60",TRUE,"60+")} -> 16-30 | Q35: =--(Table1[[#This Row],[Patient Waittime]]<=30) -> 1 | R35: =--Table1[[#This Row],[Patient Admission Flag]] -> 0 | S35: =--AND(Table1[[#This Row],[WithinTarget]]=1,Table1[[#This Row],[Patient Satisfaction Score]]>=7) -> 0 | T35: =IF(LEFT(Table1[[#This Row],[Patient Gender]],1)="F","Female","Male") -> Female
A36: P0035 | B36: 45307.837 | C36: M | D36: 14 | E36: Two or More Races | F36: None | G36: TRUE | I36: 52 | J36: TRUE | K36: =YEAR(Table1[[#This Row],[Patient Admission Date]]) -> 2024 | L36: =TEXT(Table1[[#This Row],[Patient Admission Date]],"mmm") -> Jan | M36: =TEXT(Table1[[#This Row],[Patient Admission Date]],"ddd") -> Tue | N36: =TEXT(INT(HOUR(Table1[[#This Row],[Patient Admission Date]])/3)*3,"00")&"-"&TEXT(INT(HOUR(Table1[[#This Row],[Patient Admission Date]])/3)*3+3,"00") -> 18-21 | O36: {=_xlfn.IFS(Table1[[#This Row],[Patient Age]]<=14,"0-14",Table1[[#This Row],[Patient Age]]<=29,"15-29",Table1[[#This Row],[Patient Age]]<=44,"30-44",Table1[[#This Row],[Patient Age]]<=59,"45-59",Table1[[#This Row],[Patient Age]]<=74,"60-74",TRUE,"75+")} -> 0-14 | P36: {=_xlfn.IFS(Table1[[#This Row],[Patient Waittime]]<=15,"0-15",Table1[[#This Row],[Patient Waittime]]<=30,"16-30",Table1[[#This Row],[Patient Waittime]]<=45,"31-45",Table1[[#This Row],[Patient Waittime]]<=60,"46-60",TRUE,"60+")} -> 46-60 | Q36: =--(Table1[[#This Row],[Patient Waittime]]<=30) -> 0 | R36: =--Table1[[#This Row],[Patient Admission Flag]] -> 1 | S36: =--AND(Table1[[#This Row],[WithinTarget]]=1,Table1[[#This Row],[Patient Satisfaction Score]]>=7) -> 0 | T36: =IF(LEFT(Table1[[#This Row],[Patient Gender]],1)="F","Female","Male") -> Male
A37: P0036 | B37: 45299.997 | C37: F | D37: 37 | E37: Declined to Identify | F37: None | G37: TRUE | I37: 49 | J37: TRUE | K37: =YEAR(Table1[[#This Row],[Patient Admission Date]]) -> 2024 | L37: =TEXT(Table1[[#This Row],[Patient Admission Date]],"mmm") -> Jan | M37: =TEXT(Table1[[#This Row],[Patient Admission Date]],"ddd") -> Mon | N37: =TEXT(INT(HOUR(Table1[[#This Row],[Patient Admission Date]])/3)*3,"00")&"-"&TEXT(INT(HOUR(Table1[[#This Row],[Patient Admission Date]])/3)*3+3,"00") -> 21-24 | O37: {=_xlfn.IFS(Table1[[#This Row],[Patient Age]]<=14,"0-14",Table1[[#This Row],[Patient Age]]<=29,"15-29",Table1[[#This Row],[Patient Age]]<=44,"30-44",Table1[[#This Row],[Patient Age]]<=59,"45-59",Table1[[#This Row],[Patient Age]]<=74,"60-74",TRUE,"75+")} -> 30-44 | P37: {=_xlfn.IFS(Table1[[#This Row],[Patient Waittime]]<=15,"0-15",Table1[[#This Row],[Patient Waittime]]<=30,"16-30",Table1[[#This Row],[Patient Waittime]]<=45,"31-45",Table1[[#This Row],[Patient Waittime]]<=60,"46-60",TRUE,"60+")} -> 46-60 | Q37: =--(Table1[[#This Row],[Patient Waittime]]<=30) -> 0 | R37: =--Table1[[#This Row],[Patient Admission Flag]] -> 1 | S37: =--AND(Table1[[#This Row],[WithinTarget]]=1,Table1[[#This Row],[Patient Satisfaction Score]]>=7) -> 0 | T37: =IF(LEFT(Table1[[#This Row],[Patient Gender]],1)="F","Female","Male") -> Female
A38: P0037 | B38: 45274.89 | C38: M | D38: 25 | E38: African American | F38: None | G38: FALSE | I38: 10 | J38: FALSE | K38: =YEAR(Table1[[#This Row],[Patient Admission Date]]) -> 2023 | L38: =TEXT(Table1[[#This Row],[Patient Admission Date]],"mmm") -> Dec | M38: =TEXT(Table1[[#This Row],[Patient Admission Date]],"ddd") -> Thu | N38: =TEXT(INT(HOUR(Table1[[#This Row],[Patient Admission Date]])/3)*3,"00")&"-"&TEXT(INT(HOUR(Table1[[#This Row],[Patient Admission Date]])/3)*3+3,"00") -> 21-24 | O38: {=_xlfn.IFS(Table1[[#This Row],[Patient Age]]<=14,"0-14",Table1[[#This Row],[Patient Age]]<=29,"15-29",Table1[[#This Row],[Patient Age]]<=44,"30-44",Table1[[#This Row],[Patient Age]]<=59,"45-59",Table1[[#This Row],[Patient Age]]<=74,"60-74",TRUE,"75+")} -> 15-29 | P38: {=_xlfn.IFS(Table1[[#This Row],[Patient Waittime]]<=15,"0-15",Table1[[#This Row],[Patient Waittime]]<=30,"16-30",Table1[[#This Row],[Patient Waittime]]<=45,"31-45",Table1[[#This Row],[Patient Waittime]]<=60,"46-60",TRUE,"60+")} -> 0-15 | Q38: =--(Table1[[#This Row],[Patient Waittime]]<=30) -> 1 | R38: =--Table1[[#This Row],[Patient Admission Flag]] -> 0 | S38: =--AND(Table1[[#This Row],[WithinTarget]]=1,Table1[[#This Row],[Patient Satisfaction Score]]>=7) -> 0 | T38: =IF(LEFT(Table1[[#This Row],[Patient Gender]],1)="F","Female","Male") -> Male
A39: P0038 | B39: 45485.55 | C39: M | D39: 39 | E39: Two or More Races | F39: Orthopedics | G39: FALSE | I39: 52 | J39: FALSE | K39: =YEAR(Table1[[#This Row],[Patient Admission Date]]) -> 2024 | L39: =TEXT(Table1[[#This Row],[Patient Admission Date]],"mmm") -> Jul | M39: =TEXT(Table1[[#This Row],[Patient Admission Date]],"ddd") -> Fri | N39: =TEXT(INT(HOUR(Table1[[#This Row],[Patient Admission Date]])/3)*3,"00")&"-"&TEXT(INT(HOUR(Table1[[#This Row],[Patient Admission Date]])/3)*3+3,"00") -> 12-15 | O39: {=_xlfn.IFS(Table1[[#This Row],[Patient Age]]<=14,"0-14",Table1[[#This Row],[Patient Age]]<=29,"15-29",Table1[[#This Row],[Patient Age]]<=44,"30-44",Table1[[#This Row],[Patient Age]]<=59,"45-59",Table1[[#This Row],[Patient Age]]<=74,"60-74",TRUE,"75+")} -> 30-44 | P39: {=_xlfn.IFS(Table1[[#This Row],[Patient Waittime]]<=15,"0-15",Table1[[#This Row],[Patient Waittime]]<=30,"16-30",Table1[[#This Row],[Patient Waittime]]<=45,"31-45",Table1[[#This Row],[Patient Waittime]]<=60,"46-60",TRUE,"60+")} -> 46-60 | Q39: =--(Table1[[#This Row],[Patient Waittime]]<=30) -> 0 | R39: =--Table1[[#This Row],[Patient Admission Flag]] -> 0 | S39: =--AND(Table1[[#This Row],[WithinTarget]]=1,Table1[[#This Row],[Patient Satisfaction Score]]>=7) -> 0 | T39: =IF(LEFT(Table1[[#This Row],[Patient Gender]],1)="F","Female","Male") -> Male
A40: P0039 | B40: 45444.44 | C40: M | D40: 48 | E40: Declined to Identify | F40: None | G40: FALSE | I40: 35 | J40: FALSE | K40: =YEAR(Table1[[#This Row],[Patient Admission Date]]) -> 2024 | L40: =TEXT(Table1[[#This Row],[Patient Admission Date]],"mmm") -> Jun | M40: =TEXT(Table1[[#This Row],[Patient Admission Date]],"ddd") -> Sat | N40: =TEXT(INT(HOUR(Table1[[#This Row],[Patient Admission Date]])/3)*3,"00")&"-"&TEXT(INT(HOUR(Table1[[#This Row],[Patient Admission Date]])/3)*3+3,"00") -> 09-12 | O40: {=_xlfn.IFS(Table1[[#This Row],[Patient Age]]<=14,"0-14",Table1[[#This Row],[Patient Age]]<=29,"15-29",Table1[[#This Row],[Patient Age]]<=44,"30-44",Table1[[#This Row],[Patient Age]]<=59,"45-59",Table1[[#This Row],[Patient Age]]<=74,"60-74",TRUE,"75+")} -> 45-59 | P40: {=_xlfn.IFS(Table1[[#This Row],[Patient Waittime]]<=15,"0-15",Table1[[#This Row],[Patient Waittime]]<=30,"16-30",Table1[[#This Row],[Patient Waittime]]<=45,"31-45",Table1[[#This Row],[Patient Waittime]]<=60,"46-60",TRUE,"60+")} -> 31-45 | Q40: =--(Table1[[#This Row],[Patient Waittime]]<=30) -> 0 | R40: =--Table1[[#This Row],[Patient Admission Flag]] -> 0 | S40: =--AND(Table1[[#This Row],[WithinTarget]]=1,Table1[[#This Row],[Patient Satisfaction Score]]>=7) -> 0 | T40: =IF(LEFT(Table1[[#This Row],[Patient Gender]],1)="F","Female","Male") -> Male
...

Sheet Pivot Report SHEET 
A3: Distinct Count of Patient Id | B3: Average of Patient Waittime | C3: Sum of Admitted Flag | D3: Sum of WithinTarget | E3: Sum of Satiesfied Flag | F3: Average of Patient Satisfaction Score | H3: Row Labels | I3: Distinct Count of Patient Id | J3: Average of Patient Waittime | K3: Distinct Count of Patient Id | L3: Column Labels | AA3: Row Labels | AB3: Average of Patient Waittime | AE3: Row Labels | AF3: Distinct Count of Patient Id | AI3: Row Labels | AJ3: Distinct Count of Patient Id | AM3: Row Labels | AN3: Count of Patient Id
A4: 9216 | B4: 35.259874 | C4: 4612 | D4: 3749 | E4: 370 | F4: 4.992054 | H4: Mar | I4: 506 | J4: 35.879447 | K4: Row Labels | L4: Apr | M4: Aug | N4: Dec | O4: Feb | P4: Jan | Q4: Jul | R4: Jun | S4: Mar | T4: May | U4: Nov | V4: Oct | W4: Sep | AA4: 0-14 | AB4: 35.360666 | AE4: General Practice | AF4: 1840 | AI4: 0-14 | AJ4: 1622 | AM4: Female | AN4: 2132
H5: Apr | I5: 948 | J5: 34.972574 | K5: 0-14 | L5: 168 | M5: 188 | N5: 69 | O5: 58 | P5: 105 | Q5: 173 | R5: 158 | S5: 93 | T5: 186 | U5: 88 | V5: 168 | W5: 168 | AA5: 15-29 | AB5: 35.270405 | AE5: Orthopedics | AF5: 995 | AI5: 15-29 | AJ5: 1801 | AM5: Male | AN5: 2206
H6: Aug | I6: 1024 | J6: 35.730469 | K6: 15-29 | L6: 205 | M6: 192 | N6: 100 | O6: 79 | P6: 93 | Q6: 185 | R6: 218 | S6: 94 | T6: 177 | U6: 80 | V6: 197 | W6: 181 | AA6: 30-44 | AB6: 35.650712 | AE6: Physiotherapy | AF6: 276 | AI6: 30-44 | AJ6: 1755
H7: Feb | I7: 431 | J7: 36.670534 | K7: 30-44 | L7: 165 | M7: 191 | N7: 99 | O7: 97 | P7: 94 | Q7: 163 | R7: 184 | S7: 99 | T7: 210 | U7: 95 | V7: 174 | W7: 184 | AA7: 45-59 | AB7: 35.005199 | AE7: Cardiology | AF7: 248 | AI7: 45-59 | AJ7: 1731
H8: Jan | I8: 513 | J8: 36.323587 | K8: 45-59 | L8: 168 | M8: 188 | N8: 96 | O8: 86 | P8: 96 | Q8: 205 | R8: 164 | S8: 95 | T8: 184 | U8: 85 | V8: 183 | W8: 181 | AA8: 60-74 | AB8: 35.017785 | AE8: Neurology | AF8: 193 | AI8: 60-74 | AJ8: 1743
H9: Jul | I9: 952 | J9: 34.965336 | K9: 60-74 | L9: 181 | M9: 201 | N9: 98 | O9: 83 | P9: 97 | Q9: 164 | R9: 206 | S9: 98 | T9: 188 | U9: 92 | V9: 171 | W9: 164 | AA9: 75+ | AB9: 35.25 | AE9: Gastroenterology | AF9: 178 | AI9: 75+ | AJ9: 564
H10: Jun | I10: 991 | J10: 35.544904 | K10: 75+ | L10: 61 | M10: 64 | N10: 27 | O10: 28 | P10: 28 | Q10: 62 | R10: 61 | S10: 27 | T10: 54 | U10: 24 | V10: 71 | W10: 57 | AE10: Renal | AF10: 86
H11: May | I11: 999 | J11: 35.146146
A12: Patients | B12: =GETPIVOTDATA("[Measures].[Distinct Count of Patient Id 2]",$A$3) -> 9216 | H12: Oct | I12: 964 | J12: 34.502075
A13: Avg Wait | B13: =GETPIVOTDATA("[Measures].[Average of Patient Waittime 2]",$A$3) -> 35.259874 | H13: Sep | I13: 935 | J13: 34.663102
A14: Satisfaction | B14: =GETPIVOTDATA("[Measures].[Average of Patient Satisfaction Score 2]",$A$3) -> 4.992054 | H14: Dec | I14: 489 | J14: 34.764826
A15: Admitted | B15: =GETPIVOTDATA("[Measures].[Sum of Admitted Flag]",$A$3) -> 4612 | H15: Nov | I15: 464 | J15: 35.185345 | AB15: Row Labels | AC15: Average of Patient Satisfaction Score
A16: Seen In Time | B16: =GETPIVOTDATA("[Measures].[Sum of WithinTarget]",$A$3) -> 3749 | AB16: 10-19 | AC16: 5.2635815
A17: Satisfied | B17: =GETPIVOTDATA("[Measures].[Sum of Satiesfied Flag]",$A$3) -> 370 | AB17: 20-29 | AC17: 4.9118943
A18: Admission Rate | B18: =B15/B12 -> 0.50043403 | D18: Count of Patient Id | E18: Column Labels | AB18: 30-39 | AC18: 4.7962963
D19: Row Labels | E19: Sun | F19: Mon | G19: Tue | H19: Wed | I19: Thu | J19: Fri | K19: Sat | L19: Grand Total | AB19: 40-49 | AC19: 5.0447471
D20: 00-03 | E20: 169 | F20: 163 | G20: 160 | H20: 158 | I20: 152 | J20: 171 | K20: 181 | L20: 1154 | AB20: 50-60 | AC20: 4.9381625
A21: Row Labels | B21: Count of Patient Id | D21: 03-06 | E21: 157 | F21: 187 | G21: 176 | H21: 152 | I21: 158 | J21: 153 | K21: 179 | L21: 1162 | AB21: Grand Total | AC21: 4.992054
A22: 00-03 | B22: 1154 | D22: 06-09 | E22: 166 | F22: 147 | G22: 174 | H22: 160 | I22: 183 | J22: 184 | K22: 162 | L22: 1176
A23: 03-06 | B23: 1162 | D23: 09-12 | E23: 152 | F23: 160 | G23: 167 | H23: 156 | I23: 165 | J23: 167 | K23: 173 | L23: 1140
A24: 06-09 | B24: 1176 | D24: 12-15 | E24: 164 | F24: 161 | G24: 147 | H24: 173 | I24: 163 | J24: 152 | K24: 184 | L24: 1144
A25: 09-12 | B25: 1140 | D25: 15-18 | E25: 164 | F25: 157 | G25: 170 | H25: 163 | I25: 174 | J25: 155 | K25: 148 | L25: 1131
A26: 12-15 | B26: 1144 | D26: 18-21 | E26: 170 | F26: 179 | G26: 134 | H26: 145 | I26: 168 | J26: 164 | K26: 165 | L26: 1125
A27: 15-18 | B27: 1131 | D27: 21-24 | E27: 176 | F27: 160 | G27: 177 | H27: 153 | I27: 169 | J27: 164 | K27: 185 | L27: 1184
A28: 18-21 | B28: 1125 | D28: Grand Total | E28: 1318 | F28: 1314 | G28: 1305 | H28: 1260 | I28: 1332 | J28: 1310 | K28: 1377 | L28: 9216
A29: 21-24 | B29: 1184

Sheet Chart Data
A1: GAUGE DATA
A2: Max | B2: =90 -> 90
A3: Target | B3: =30 -> 30
A4: Value | B4: =MIN('Pivot Report SHEET '!B13,'Chart Data'!B2) -> 35.259874
A5: Rest | B5: =B2-B4 -> 54.740126
A6: Hidden | B6: =B2 -> 90
A9: Stage | B9: Spacer | C9: Value
A10: Arrived | B10: =(MAX($C$10:$C$12)-C10)/2 -> 0 | C10: ='Pivot Report SHEET '!B12 -> 9216
A11: Seen Within target | B11: =(MAX($C$10:$C$12)-C11)/2 -> 2733.5 | C11: ='Pivot Report SHEET '!B16 -> 3749
A12: Satisfied | B12: =(MAX($C$10:$C$12)-C12)/2 -> 4423 | C12: ='Pivot Report SHEET '!B17 -> 370
A16: ="Total Patients Processed : "&TEXT('Pivot Report SHEET '!B12,"#,##0") -> Total Patients Processed : 9,216
A17: ="Seen within target: "&TEXT('Pivot Report SHEET '!B16/'Pivot Report SHEET '!B12,"0%") -> Seen within target: 41%
A18: ="Satisfaction Rating: "&TEXT('Pivot Report SHEET '!B14,"0.0")&"/5.0 | Admission Rate: "&TEXT('Pivot Report SHEET '!B18,"0%") -> Satisfaction Rating: 5.0/5.0 | Admission Rate: 50%
A19: ="Target: "&B3&" MIN | Current AVG: "&TEXT('Pivot Report SHEET '!B13,"0.0")&"min ("&IF('Pivot Report SHEET '!B13<=B3,"on target","above target")&")" -> Target: 30 MIN | Current AVG: 35.3min (above target)

Sheet Dashboard
A1: s
G28: S
